<?xml version="1.0" ?>
<!-- =================================================================================== -->
<!-- |    This document was autogenerated by xacro from mbot_base.xacro                | -->
<!-- |    EDITING THIS FILE BY HAND IS NOT RECOMMENDED                                 | -->
<!-- =================================================================================== -->
<robot name="mbot">
  <material name="white">
    <color rgba="1 1 1 1"/>
  </material>
  <material name="red">
    <color rgba="1 0 0 0.8"/>
  </material>
  <material name="grey">
    <color rgba="0.5 0.5 0.5 1"/>
  </material>
  <material name="black">
    <color rgba="0 0 0 1"/>
  </material>
  <!-- link base_footprint -->
  <link name="base_footprint">
    <visual>
      <origin rpy="0 0 0" xyz="0 0 0"/>
      <geometry>
        <box size="0.001 0.001 0.001"/>
      </geometry>
    </visual>
  </link>
  <gazebo reference="base_footprint">
    <turnGravityOff>false</turnGravityOff>
  </gazebo>
  <joint name="base_link_joint" type="fixed">
    <origin rpy="0 0 0" xyz="0 0 0.11"/>
    <parent link="base_footprint"/>
    <child link="base_link"/>
  </joint>
  <link name="base_link">
    <visual>
      <origin rpy="0 0 0" xyz="0 0 0"/>
      <geometry>
        <cylinder length="0.16" radius="0.2"/>
      </geometry>
      <material name="red"/>
    </visual>
    <collision>
      <origin rpy="0 0 0" xyz=" 0 0 0"/>
      <geometry>
        <cylinder length="0.16" radius="0.2"/>
      </geometry>
    </collision>
    <inertial>
      <mass value="1"/>
      <inertia ixx="0.012133333333333336" ixy="0" ixz="0" iyy="0.012133333333333336" iyz="0" izz="0.020000000000000004"/>
    </inertial>
  </link>
  <gazebo reference="base_link">
    <material>Gazebo/Red</material>
  </gazebo>
  <joint name="stage_joint" type="fixed">
    <origin rpy="0 0 0" xyz="0 0 0.13"/>
    <parent link="base_link"/>
    <child link="stage_link"/>
  </joint>
  <link name="stage_link">
    <visual>
      <origin rpy="0 0 0" xyz="0 0 0"/>
      <geometry>
        <cylinder length="0.1" radius="0.1"/>
      </geometry>
      <material name="red"/>
    </visual>
    <collision>
      <origin rpy="0 0 0" xyz=" 0 0 0"/>
      <geometry>
        <cylinder length="0.1" radius="0.1"/>
      </geometry>
    </collision>
    <inertial>
      <mass value="0.5"/>
      <inertia ixx="0.001666666666666667" ixy="0" ixz="0" iyy="0.001666666666666667" iyz="0" izz="0.0025000000000000005"/>
    </inertial>
  </link>
  <gazebo reference="stage_link">
    <material>Gazebo/Red</material>
  </gazebo>
  <joint name="stage2_joint" type="fixed">
    <origin rpy="0 0 0" xyz="0 0 0.07"/>
    <parent link="stage_link"/>
    <child link="stage2_link"/>
  </joint>
  <link name="stage2_link">
    <visual>
      <origin rpy="0 0 0" xyz="0 0 0"/>
      <geometry>
        <cylinder length="0.04" radius="0.05"/>
      </geometry>
      <material name="grey"/>
    </visual>
    <collision>
      <origin rpy="0 0 0" xyz=" 0 0 0"/>
      <geometry>
        <cylinder length="0.04" radius="0.05"/>
      </geometry>
    </collision>
    <inertial>
      <mass value="0.3"/>
      <inertia ixx="0.00022750000000000005" ixy="0" ixz="0" iyy="0.00022750000000000005" iyz="0" izz="0.000375"/>
    </inertial>
  </link>
  <gazebo reference="stage2_link">
    <material>Gazebo/Grey</material>
  </gazebo>
  <joint name="z_rotator_joint" type="continuous">
    <origin rpy="0 0 0" xyz="0 0 0.12000000000000001"/>
    <parent link="stage2_link"/>
    <child link="z_rotator_link"/>
    <axis xyz="0 0 1"/>
  </joint>
  <link name="z_rotator_link">
    <visual>
      <origin rpy="0 0 0" xyz="0 0 0"/>
      <geometry>
        <box size="0.06 0.06 0.2"/>
      </geometry>
      <material name="grey"/>
    </visual>
    <collision>
      <origin rpy="0 0 0" xyz=" 0 0 0"/>
      <geometry>
        <box size="0.06 0.06 0.2"/>
      </geometry>
    </collision>
    <inertial>
      <mass value="0.1"/>
      <inertia ixx="0.0003633333333333334" ixy="0" ixz="0" iyy="0.0003633333333333334" iyz="0" izz="6e-05"/>
    </inertial>
  </link>
  <gazebo reference="z_rotator">
    <material>Gazebo/Grey</material>
  </gazebo>
  <joint name="y_rotator_joint" type="revolute">
    <origin rpy="0 0 0" xyz="0 0 0.12100000000000001"/>
    <parent link="z_rotator_link"/>
    <child link="y_rotator_link"/>
    <limit effort="10" lower="-1.047" upper="1.047" velocity="1.0"/>
    <axis xyz="0 1 0"/>
  </joint>
  <link name="y_rotator_link">
    <visual>
      <origin rpy=" 1.571 0 0" xyz="0 0 0"/>
      <geometry>
        <cylinder length="0.055" radius="0.03"/>
      </geometry>
      <material name="grey"/>
    </visual>
    <collision>
      <origin rpy="1.571 0 0" xyz=" 0 0 0"/>
      <geometry>
        <cylinder length="0.055" radius="0.03"/>
      </geometry>
    </collision>
    <inertial>
      <mass value="0.1"/>
      <inertia ixx="4.770833333333333e-05" ixy="0" ixz="0" iyy="4.770833333333333e-05" iyz="0" izz="4.4999999999999996e-05"/>
    </inertial>
  </link>
  <gazebo reference="y_rotator_link">
    <material>Gazebo/Grey</material>
  </gazebo>
  <joint name="camera_shell_joint" type="fixed">
    <origin rpy="0 0 0" xyz="0.04 0 0.056"/>
    <parent link="y_rotator_link"/>
    <child link="camera_shell_link"/>
  </joint>
  <link name="camera_shell_link">
    <visual>
      <origin rpy="0 0 0" xyz="0 0 0"/>
      <geometry>
        <box size="0.2 0.07 0.07"/>
      </geometry>
      <material name="white"/>
    </visual>
    <collision>
      <origin rpy="0 0 0" xyz=" 0 0 0"/>
      <geometry>
        <box size="0.2 0.07 0.07"/>
      </geometry>
    </collision>
    <inertial>
      <mass value="0.01"/>
      <inertia ixx="3.741666666666668e-05" ixy="0" ixz="0" iyy="8.166666666666668e-06" iyz="0" izz="3.741666666666668e-05"/>
    </inertial>
  </link>
  <gazebo reference="camera_shell">
    <material>Gazebo/White</material>
  </gazebo>
  <transmission name="z_rotator_joint_trans">
    <type>transmission_interface/SimpleTransmission</type>
    <joint name="z_rotator_joint">
      <hardwareInterface>EffortJointInterface</hardwareInterface>
    </joint>
    <actuator name="z_rotator_joint_motor">
      <hardwareInterface>EffortJointInterface</hardwareInterface>
      <mechanicalReduction>1</mechanicalReduction>
    </actuator>
  </transmission>
  <transmission name="y_rotator_joint_trans">
    <type>transmission_interface/SimpleTransmission</type>
    <joint name="y_rotator_joint_joint">
      <hardwareInterface>EffortJointInterface</hardwareInterface>
    </joint>
    <actuator name="y_rotator_joint_motor">
      <hardwareInterface>EffortJointInterface</hardwareInterface>
      <mechanicalReduction>1</mechanicalReduction>
    </actuator>
  </transmission>
  <joint name="left_wheel_joint" type="continuous">
    <origin rpy="0 0 0" xyz="0 0.19 -0.05"/>
    <parent link="base_link"/>
    <child link="left_wheel_link"/>
    <axis xyz="0 1 0"/>
  </joint>
  <link name="left_wheel_link">
    <visual>
      <origin rpy="1.5707963 0 0" xyz="0 0 0"/>
      <geometry>
        <cylinder length="0.06" radius="0.06"/>
      </geometry>
      <material name="white"/>
    </visual>
    <collision>
      <origin rpy="1.5707963 0 0" xyz="0 0 0"/>
      <geometry>
        <cylinder length="0.06" radius="0.06"/>
      </geometry>
    </collision>
    <inertial>
      <mass value="0.2"/>
      <inertia ixx="0.00024" ixy="0" ixz="0" iyy="0.00024" iyz="0" izz="0.00035999999999999997"/>
    </inertial>
  </link>
  <gazebo reference="left_wheel_link">
    <material>Gazebo/White</material>
  </gazebo>
  <!-- Transmission is important to link the joints and the controller -->
  <transmission name="left_wheel_joint_trans">
    <type>transmission_interface/SimpleTransmission</type>
    <joint name="left_wheel_joint">
      <hardwareInterface>hardware_interface/VelocityJointInterface</hardwareInterface>
    </joint>
    <actuator name="left_wheel_joint_motor">
      <hardwareInterface>hardware_interface/VelocityJointInterface</hardwareInterface>
      <mechanicalReduction>1</mechanicalReduction>
    </actuator>
  </transmission>
  <joint name="right_wheel_joint" type="continuous">
    <origin rpy="0 0 0" xyz="0 -0.19 -0.05"/>
    <parent link="base_link"/>
    <child link="right_wheel_link"/>
    <axis xyz="0 1 0"/>
  </joint>
  <link name="right_wheel_link">
    <visual>
      <origin rpy="1.5707963 0 0" xyz="0 0 0"/>
      <geometry>
        <cylinder length="0.06" radius="0.06"/>
      </geometry>
      <material name="white"/>
    </visual>
    <collision>
      <origin rpy="1.5707963 0 0" xyz="0 0 0"/>
      <geometry>
        <cylinder length="0.06" radius="0.06"/>
      </geometry>
    </collision>
    <inertial>
      <mass value="0.2"/>
      <inertia ixx="0.00024" ixy="0" ixz="0" iyy="0.00024" iyz="0" izz="0.00035999999999999997"/>
    </inertial>
  </link>
  <gazebo reference="right_wheel_link">
    <material>Gazebo/White</material>
  </gazebo>
  <!-- Transmission is important to link the joints and the controller -->
  <transmission name="right_wheel_joint_trans">
    <type>transmission_interface/SimpleTransmission</type>
    <joint name="right_wheel_joint">
      <hardwareInterface>hardware_interface/VelocityJointInterface</hardwareInterface>
    </joint>
    <actuator name="right_wheel_joint_motor">
      <hardwareInterface>hardware_interface/VelocityJointInterface</hardwareInterface>
      <mechanicalReduction>1</mechanicalReduction>
    </actuator>
  </transmission>
  <joint name="front_caster_joint" type="continuous">
    <origin rpy="0 0 0" xyz="0.18 0 -0.095"/>
    <parent link="base_link"/>
    <child link="front_caster_link"/>
    <axis xyz="0 1 0"/>
  </joint>
  <link name="front_caster_link">
    <visual>
      <origin rpy="0 0 0" xyz="0 0 0"/>
      <geometry>
        <sphere radius="0.015"/>
      </geometry>
      <material name="white"/>
    </visual>
    <collision>
      <origin rpy="0 0 0" xyz="0 0 0"/>
      <geometry>
        <sphere radius="0.015"/>
      </geometry>
    </collision>
    <inertial>
      <mass value="0.1"/>
      <inertia ixx="8.999999999999999e-06" ixy="0" ixz="0" iyy="8.999999999999999e-06" iyz="0" izz="8.999999999999999e-06"/>
    </inertial>
  </link>
  <gazebo reference="front_caster_link">
    <material>Gazebo/White</material>
  </gazebo>
  <gazebo>
    <plugin filename="libgazebo_ros_control.so" name="gazebo_ros_control">
      <robotNamespace>/mbot</robotNamespace>
      <robotSimType>gazebo_ros_control/DefaultRobotHWSim</robotSimType>
    </plugin>
  </gazebo>
  <joint name="back_caster_joint" type="continuous">
    <origin rpy="0 0 0" xyz="-0.18 0 -0.095"/>
    <parent link="base_link"/>
    <child link="back_caster_link"/>
    <axis xyz="0 1 0"/>
  </joint>
  <link name="back_caster_link">
    <visual>
      <origin rpy="0 0 0" xyz="0 0 0"/>
      <geometry>
        <sphere radius="0.015"/>
      </geometry>
      <material name="white"/>
    </visual>
    <collision>
      <origin rpy="0 0 0" xyz="0 0 0"/>
      <geometry>
        <sphere radius="0.015"/>
      </geometry>
    </collision>
    <inertial>
      <mass value="0.1"/>
      <inertia ixx="8.999999999999999e-06" ixy="0" ixz="0" iyy="8.999999999999999e-06" iyz="0" izz="8.999999999999999e-06"/>
    </inertial>
  </link>
  <gazebo reference="back_caster_link">
    <material>Gazebo/White</material>
  </gazebo>
  <gazebo>
    <plugin filename="libgazebo_ros_control.so" name="gazebo_ros_control">
      <robotNamespace>/mbot</robotNamespace>
      <robotSimType>gazebo_ros_control/DefaultRobotHWSim</robotSimType>
    </plugin>
  </gazebo>
  <!-- controller -->
  <gazebo>
    <plugin filename="libgazebo_ros_diff_drive.so" name="differential_drive_controller">
      <rosDebugLevel>Debug</rosDebugLevel>
      <publishWheelTF>true</publishWheelTF>
      <robotNamespace>/</robotNamespace>
      <publishTf>1</publishTf>
      <publishWheelJointState>true</publishWheelJointState>
      <alwaysOn>true</alwaysOn>
      <updateRate>100.0</updateRate>
      <legacyMode>true</legacyMode>
      <leftJoint>left_wheel_joint</leftJoint>
      <rightJoint>right_wheel_joint</rightJoint>
      <wheelSeparation>0.38</wheelSeparation>
      <wheelDiameter>0.12</wheelDiameter>
      <broadcastTF>1</broadcastTF>
      <wheelTorque>30</wheelTorque>
      <wheelAcceleration>1.8</wheelAcceleration>
      <commandTopic>cmd_vel</commandTopic>
      <odometryFrame>odom</odometryFrame>
      <odometryTopic>odom</odometryTopic>
      <robotBaseFrame>base_footprint</robotBaseFrame>
    </plugin>
  </gazebo>
  <joint name="camera_joint" type="fixed">
    <origin rpy="0 0 0" xyz="0.1 0 0"/>
    <parent link="camera_shell_link"/>
    <child link="camera_link"/>
  </joint>
  <link name="camera_link">
    <visual>
      <origin rpy="0 1.5707963 0" xyz="0 0 0"/>
      <geometry>
        <cylinder length="0.01" radius="0.025"/>
      </geometry>
      <material name="black"/>
    </visual>
    <collision>
      <origin rpy="0 0 0" xyz="0.0 0.0 0.0"/>
      <geometry>
        <cylinder length="0.01" radius="0.025"/>
      </geometry>
    </collision>
    <inertial>
      <mass value="0.1"/>
      <origin xyz="0 0 0"/>
      <inertia ixx="0.01" ixy="0.0" ixz="0.0" iyy="0.01" iyz="0.0" izz="0.01"/>
    </inertial>
  </link>
  <gazebo reference="camera_link">
    <material>Gazebo/Black</material>
  </gazebo>
  <gazebo reference="camera_link">
    <sensor name="camera_node" type="camera">
      <update_rate>30.0</update_rate>
      <camera name="head">
        <horizontal_fov>1.3962634</horizontal_fov>
        <image>
          <width>1280</width>
          <height>720</height>
          <format>R8G8B8</format>
        </image>
        <clip>
          <near>0.02</near>
          <far>300</far>
        </clip>
        <noise>
          <type>gaussian</type>
          <mean>0.0</mean>
          <stddev>0.007</stddev>
        </noise>
      </camera>
      <plugin filename="libgazebo_ros_camera.so" name="gazebo_camera">
        <alwaysOn>true</alwaysOn>
        <updateRate>0.0</updateRate>
        <cameraName>/camera</cameraName>
        <imageTopicName>image_raw</imageTopicName>
        <cameraInfoTopicName>camera_info</cameraInfoTopicName>
        <frameName>camera_link</frameName>
        <hackBaseline>0.07</hackBaseline>
        <distortionK1>0.0</distortionK1>
        <distortionK2>0.0</distortionK2>
        <distortionK3>0.0</distortionK3>
        <distortionT1>0.0</distortionT1>
        <distortionT2>0.0</distortionT2>
      </plugin>
    </sensor>
  </gazebo>
  <joint name="kinect_joint" type="fixed">
    <origin rpy="0 0 0" xyz="0.15 0 0.11"/>
    <parent link="base_link"/>
    <child link="kinect_link"/>
  </joint>
  <link name="kinect_link">
    <visual>
      <origin rpy="0 0 1.5707963" xyz="0 0 0"/>
      <geometry>
        <mesh filename="package://gazebo_test/meshes/kinect.dae"/>
      </geometry>
    </visual>
    <collision>
      <geometry>
        <box size="0.07 0.3 0.09"/>
      </geometry>
    </collision>
  </link>
  <joint name="kinect_optical_joint" type="fixed">
    <origin rpy="-1.5708 0 -1.5708" xyz="0 0 0"/>
    <parent link="kinect_link"/>
    <child link="kinect_frame_optical"/>
  </joint>
  <link name="kinect_frame_optical"/>
  <gazebo reference="kinect_link">
    <sensor name="kinect" type="depth">
      <always_on>true</always_on>
      <update_rate>20.0</update_rate>
      <camera>
        <horizontal_fov>1.0471975333333332</horizontal_fov>
        <image>
          <format>R8G8B8</format>
          <width>640</width>
          <height>480</height>
        </image>
        <clip>
          <near>0.05</near>
          <far>8.0</far>
        </clip>
      </camera>
      <plugin filename="libgazebo_ros_openni_kinect.so" name="kinect_kinect_controller">
        <cameraName>kinect</cameraName>
        <alwaysOn>true</alwaysOn>
        <updateRate>10</updateRate>
        <imageTopicName>rgb/image_raw</imageTopicName>
        <depthImageTopicName>depth/image_raw</depthImageTopicName>
        <pointCloudTopicName>depth/points</pointCloudTopicName>
        <cameraInfoTopicName>rgb/camera_info</cameraInfoTopicName>
        <depthImageCameraInfoTopicName>depth/camera_info</depthImageCameraInfoTopicName>
        <frameName>kinect_frame_optical</frameName>
        <baseline>0.1</baseline>
        <distortion_k1>0.0</distortion_k1>
        <distortion_k2>0.0</distortion_k2>
        <distortion_k3>0.0</distortion_k3>
        <distortion_t1>0.0</distortion_t1>
        <distortion_t2>0.0</distortion_t2>
        <pointCloudCutoff>0.4</pointCloudCutoff>
      </plugin>
    </sensor>
  </gazebo>
</robot>

